Workbook
Name BudgetLimit: Dashboard!$C$12
Name BudgetTarget: Dashboard!$C$11
Name Sources: Lists!$B$2:$B$20
Name Subsystems: Lists!$A$2:$A$20
Name Vendors: Lists!$C$2:$C$20

Sheet Dashboard
B2: Component Costs
B3: 3D hologram-like RGB LED fan display
B5: Total value | C5: Spent | D5: Recovered | E5: Budget left
B6: =SUM('Components'!$I$6:$I$300) -> 8673.99 | C6: =SUMIFS('Components'!$I$6:$I$300,'Components'!$J$6:$J$300,"Purchased") -> 4609.99 | D6: =SUM('Components'!$I$6:$I$300)-SUMIFS('Components'!$I$6:$I$300,'Components'!$J$6:$J$300,"Purchased") -> 4064 | E6: =BudgetLimit-SUMIFS('Components'!$I$6:$I$300,'Components'!$J$6:$J$300,"Purchased") -> 390.01
B9: Budget | G9: Cost by subsystem
B10: Spent | C10: =SUMIFS('Components'!$I$6:$I$300,'Components'!$J$6:$J$300,"Purchased") -> 4609.99
B11: Target | C11: 4500
B12: Limit | C12: 5000
B13: Used | C13: =SUMIFS('Components'!$I$6:$I$300,'Components'!$J$6:$J$300,"Purchased")/BudgetLimit -> 0.921998 | D13: =REPT("█",ROUND(MIN(1,SUMIFS('Components'!$I$6:$I$300,'Components'!$J$6:$J$300,"Purchased")/BudgetLimit)*20,0)) -> ██████████████████
B14: Status | C14: =IF(SUMIFS('Components'!$I$6:$I$300,'Components'!$J$6:$J$300,"Purchased")<=BudgetTarget,"Under target",IF(SUMIFS('Components'!$I$6:$I$300,'Components'!$J$6:$J$300,"Purchased")<=BudgetLimit,"Within limit","Over budget")) -> Within limit
B15: Yellow cells can be edited.
B17: By subsystem
B18: Subsystem | C18: Spent | D18: Recovered | E18: Total
B19: Rotor | C19: =SUMIFS('Components'!$I$6:$I$300,'Components'!$D$6:$D$300,B19,'Components'!$J$6:$J$300,"Purchased") -> 2000.24 | D19: =SUMIFS('Components'!$I$6:$I$300,'Components'!$D$6:$D$300,B19,'Components'!$J$6:$J$300,"Recovered") -> 1813.5 | E19: =C19+D19 -> 3813.74
B20: Stator | C20: =SUMIFS('Components'!$I$6:$I$300,'Components'!$D$6:$D$300,B20,'Components'!$J$6:$J$300,"Purchased") -> 1531.75 | D20: =SUMIFS('Components'!$I$6:$I$300,'Components'!$D$6:$D$300,B20,'Components'!$J$6:$J$300,"Recovered") -> 613.8 | E20: =C20+D20 -> 2145.55
B21: Linear rail | C21: =SUMIFS('Components'!$I$6:$I$300,'Components'!$D$6:$D$300,B21,'Components'!$J$6:$J$300,"Purchased") -> 300.48 | D21: =SUMIFS('Components'!$I$6:$I$300,'Components'!$D$6:$D$300,B21,'Components'!$J$6:$J$300,"Recovered") -> 1636.7 | E21: =C21+D21 -> 1937.18
B22: Enclosure | C22: =SUMIFS('Components'!$I$6:$I$300,'Components'!$D$6:$D$300,B22,'Components'!$J$6:$J$300,"Purchased") -> 529.12 | D22: =SUMIFS('Components'!$I$6:$I$300,'Components'!$D$6:$D$300,B22,'Components'!$J$6:$J$300,"Recovered") -> 0 | E22: =C22+D22 -> 529.12
B23: Wiring & hardware | C23: =SUMIFS('Components'!$I$6:$I$300,'Components'!$D$6:$D$300,B23,'Components'!$J$6:$J$300,"Purchased") -> 248.4 | D23: =SUMIFS('Components'!$I$6:$I$300,'Components'!$D$6:$D$300,B23,'Components'!$J$6:$J$300,"Recovered") -> 0 | E23: =C23+D23 -> 248.4
B24: Total | C24: =SUM(C19:C23) -> 4609.99 | D24: =SUM(D19:D23) -> 4064 | E24: =SUM(E19:E23) -> 8673.99
B27: By vendor
B28: Vendor | C28: Spent | D28: Recovered | E28: Total
B29: MicroRobotics | C29: =SUMIFS('Components'!$I$6:$I$300,'Components'!$E$6:$E$300,B29,'Components'!$J$6:$J$300,"Purchased") -> 2819.8 | D29: =SUMIFS('Components'!$I$6:$I$300,'Components'!$E$6:$E$300,B29,'Components'!$J$6:$J$300,"Recovered") -> 1202.9 | E29: =C29+D29 -> 4022.7
B30: DIYElectronics | C30: =SUMIFS('Components'!$I$6:$I$300,'Components'!$E$6:$E$300,B30,'Components'!$J$6:$J$300,"Purchased") -> 259.13 | D30: =SUMIFS('Components'!$I$6:$I$300,'Components'!$E$6:$E$300,B30,'Components'!$J$6:$J$300,"Recovered") -> 1894 | E30: =C30+D30 -> 2153.13
B31: RS Components | C31: =SUMIFS('Components'!$I$6:$I$300,'Components'!$E$6:$E$300,B31,'Components'!$J$6:$J$300,"Purchased") -> 0 | D31: =SUMIFS('Components'!$I$6:$I$300,'Components'!$E$6:$E$300,B31,'Components'!$J$6:$J$300,"Recovered") -> 967.1 | E31: =C31+D31 -> 967.1
B32: M&M Labs | C32: =SUMIFS('Components'!$I$6:$I$300,'Components'!$E$6:$E$300,B32,'Components'!$J$6:$J$300,"Purchased") -> 1001.94 | D32: =SUMIFS('Components'!$I$6:$I$300,'Components'!$E$6:$E$300,B32,'Components'!$J$6:$J$300,"Recovered") -> 0 | E32: =C32+D32 -> 1001.94
B33: Ahmed's Textiles | C33: =SUMIFS('Components'!$I$6:$I$300,'Components'!$E$6:$E$300,B33,'Components'!$J$6:$J$300,"Purchased") -> 348.12 | D33: =SUMIFS('Components'!$I$6:$I$300,'Components'!$E$6:$E$300,B33,'Components'!$J$6:$J$300,"Recovered") -> 0 | E33: =C33+D33 -> 348.12
B34: TimBuild | C34: =SUMIFS('Components'!$I$6:$I$300,'Components'!$E$6:$E$300,B34,'Components'!$J$6:$J$300,"Purchased") -> 181 | D34: =SUMIFS('Components'!$I$6:$I$300,'Components'!$E$6:$E$300,B34,'Components'!$J$6:$J$300,"Recovered") -> 0 | E34: =C34+D34 -> 181
B35: Total | C35: =SUM(C29:C34) -> 4609.99 | D35: =SUM(D29:D34) -> 4064 | E35: =SUM(E29:E34) -> 8673.99

Sheet Components
B2: Components
B3: From Table 8 of the report. Shaded rows were recovered at no cost.
B5: # | C5: Component | D5: Subsystem | E5: Vendor | F5: SKU | G5: Unit cost | H5: Qty | I5: Total | J5: Source | K5: Link
B6: 1 | C6: FireBeetle 2 ESP32-S3 | D6: Rotor | E6: MicroRobotics | G6: 423.2 | H6: 2 | I6: =G6*H6 -> 846.4 | J6: Recovered
B7: 2 | C7: FireBeetle 2 ESP32-S3 | D7: Rotor | E7: MicroRobotics | G7: 423.2 | H7: 1 | I7: =G7*H7 -> 423.2 | J7: Purchased
B8: 3 | C8: DotStar LED strip, 144 LED/m, 500 mm | D8: Rotor | E8: RS Components | F8: 124-5482 | G8: 967.1 | H8: 1 | I8: =G8*H8 -> 967.1 | J8: Recovered | K8: Link
B9: 4 | C9: LiPo battery 5000 mAh 3.7 V | D9: Rotor | E9: MicroRobotics | F9: 955565 | G9: 158.7 | H9: 2 | I9: =G9*H9 -> 317.4 | J9: Purchased | K9: Link
B10: 5 | C10: USB-C LiPo charger | D10: Rotor | E10: MicroRobotics | F10: PK4056 | G10: 18.4 | H10: 2 | I10: =G10*H10 -> 36.8 | J10: Purchased | K10: Link
B11: 6 | C11: Pololu boost regulator 5 V 3 A | D11: Rotor | E11: MicroRobotics | F11: 4082 | G11: 308.2 | H11: 2 | I11: =G11*H11 -> 616.4 | J11: Purchased | K11: Link
B12: 7 | C12: A3144E Hall effect sensor (4 pack) | D12: Rotor | E12: MicroRobotics | F12: A3144E | G12: 13.8 | H12: 1 | I12: =G12*H12 -> 13.8 | J12: Purchased | K12: Link
B13: 8 | C13: Neodymium magnets 6x3 mm (5 pack) | D13: Rotor | E13: DIYElectronics | F13: 9MAGNDN42D6X3 | G13: 39.13 | H13: 2 | I13: =G13*H13 -> 78.26 | J13: Purchased | K13: Link
B14: 9 | C14: Rotor body (3D printed) | D14: Rotor | E14: M&M Labs | G14: 160.36 | H14: 2 | I14: =G14*H14 -> 320.72 | J14: Purchased
B15: 10 | C15: LED strip holder (3D printed) | D15: Rotor | E15: M&M Labs | G15: 96.83 | H15: 2 | I15: =G15*H15 -> 193.66 | J15: Purchased
B16: 11 | C16: 2804 BLDC motor with AS5600 encoder | D16: Stator | E16: MicroRobotics | F16: FIT1034 | G16: 434.7 | H16: 2 | I16: =G16*H16 -> 869.4 | J16: Purchased | K16: Link
B17: 12 | C17: SimpleFOC Mini motor driver | D17: Stator | E17: MicroRobotics | F17: DRI0058 | G17: 138 | H17: 2 | I17: =G17*H17 -> 276 | J17: Purchased | K17: Link
B18: 13 | C18: FireBeetle 2 ESP32-C6 | D18: Stator | E18: DIYElectronics | F18: 9MDFFIREB2ESP32 | G18: 139 | H18: 2 | I18: =G18*H18 -> 278 | J18: Recovered | K18: Link
B19: 14 | C19: Buck converter, 5 V output | D19: Stator | E19: DIYElectronics | F19: 9MDCDCFO5V | G19: 33.045 | H19: 2 | I19: =G19*H19 -> 66.09 | J19: Purchased | K19: Link
B20: 15 | C20: AC adapter 12 V 5 A | D20: Stator | E20: MicroRobotics | F20: AC-12V5A-2155 | G20: 167.9 | H20: 2 | I20: =G20*H20 -> 335.8 | J20: Recovered | K20: Link
B21: 16 | C21: TO220 heatsink (4 pack) | D21: Stator | E21: MicroRobotics | F21: TO220H-KIT | G21: 18.4 | H21: 1 | I21: =G21*H21 -> 18.4 | J21: Purchased | K21: Link
B22: 17 | C22: Stator body (3D printed) | D22: Stator | E22: M&M Labs | G22: 150.93 | H22: 2 | I22: =G22*H22 -> 301.86 | J22: Purchased
B23: 18 | C23: NEMA17 stepper motor | D23: Linear rail | E23: DIYElectronics | G23: 237 | H23: 1 | I23: =G23*H23 -> 237 | J23: Recovered | K23: Link
B24: 19 | C24: A4988 stepper driver | D24: Linear rail | E24: DIYElectronics | G24: 29 | H24: 1 | I24: =G24*H24 -> 29 | J24: Recovered | K24: Link
B25: 20 | C25: V-slot aluminium extrusion | D25: Linear rail | E25: DIYElectronics | G25: 170 | H25: 4 | I25: =G25*H25 -> 680 | J25: Recovered
B26: 21 | C26: V-wheel | D26: Linear rail | E26: DIYElectronics | G26: 19 | H26: 16 | I26: =G26*H26 -> 304 | J26: Recovered
B27: 22 | C27: GT2 timing belt 1220 mm | D27: Linear rail | E27: DIYElectronics | G27: 111 | H27: 1 | I27: =G27*H27 -> 111 | J27: Recovered
B28: 23 | C28: GT2 timing pulley | D28: Linear rail | E28: DIYElectronics | G28: 47 | H28: 2 | I28: =G28*H28 -> 94 | J28: Recovered
B29: 24 | C29: Pillow block bearing 8 mm | D29: Linear rail | E29: DIYElectronics | G29: 35 | H29: 4 | I29: =G29*H29 -> 140 | J29: Recovered
B30: 25 | C30: Flexible shaft coupling | D30: Linear rail | E30: DIYElectronics | G30: 21 | H30: 1 | I30: =G30*H30 -> 21 | J30: Recovered
B31: 26 | C31: Limit switch | D31: Linear rail | E31: MicroRobotics | G31: 10.35 | H31: 2 | I31: =G31*H31 -> 20.7 | J31: Recovered
B32: 27 | C32: E18-D80NK IR sensor | D32: Linear rail | E32: DIYElectronics | F32: 9MIRSENSOR | G32: 57.39 | H32: 2 | I32: =G32*H32 -> 114.78 | J32: Purchased | K32: Link
B33: 28 | C33: Carriage mount (laser cut) | D33: Linear rail | E33: M&M Labs | G33: 92.85 | H33: 2 | I33: =G33*H33 -> 185.7 | J33: Purchased
B34: 29 | C34: Clear PVC sheet, 1 m | D34: Enclosure | E34: Ahmed's Textiles | G34: 87.03 | H34: 4 | I34: =G34*H34 -> 348.12 | J34: Purchased
B35: 30 | C35: Pine wood, 3 m | D35: Enclosure | E35: TimBuild | G35: 55 | H35: 3 | I35: =G35*H35 -> 165 | J35: Purchased
B36: 31 | C36: Panel pins 40 mm | D36: Enclosure | E36: TimBuild | G36: 16 | H36: 1 | I36: =G36*H36 -> 16 | J36: Purchased
B37: 32 | C37: 26AWG wire, black, 5 m | D37: Wiring & hardware | E37: MicroRobotics | F37: UL2007-BLK-5M | G37: 9.2 | H37: 1 | I37: =G37*H37 -> 9.2 | J37: Purchased | K37: Link
B38: 33 | C38: 26AWG wire, red, 5 m | D38: Wiring & hardware | E38: MicroRobotics | F38: UL2007-RED-5M | G38: 9.2 | H38: 1 | I38: =G38*H38 -> 9.2 | J38: Purchased | K38: Link
B39: 34 | C39: M3 bolt and spacer kit | D39: Wiring & hardware | E39: MicroRobotics | G39: 25.3 | H39: 2 | I39: =G39*H39 -> 50.6 | J39: Purchased
B40: 35 | C40: M2.5 bolt and spacer kit | D40: Wiring & hardware | E40: MicroRobotics | G40: 20.7 | H40: 2 | I40: =G40*H40 -> 41.4 | J40: Purchased
B41: 36 | C41: M2 bolt and spacer kit | D41: Wiring & hardware | E41: MicroRobotics | G41: 23 | H41: 1 | I41: =G41*H41 -> 23 | J41: Purchased
B42: 37 | C42: KF120 screw terminals | D42: Wiring & hardware | E42: MicroRobotics | G42: 36.8 | H42: 2 | I42: =G42*H42 -> 73.6 | J42: Purchased
...

Sheet Lists
A1: Subsystems | B1: Sources | C1: Vendors
A2: Rotor | B2: Purchased | C2: MicroRobotics
A3: Stator | B3: Recovered | C3: DIYElectronics
A4: Linear rail | C4: RS Components
A5: Enclosure | C5: M&M Labs
A6: Wiring & hardware | C6: Ahmed's Textiles
C7: TimBuild
